[2022-09-21T21:10:45.721+0000] {taskinstance.py:1171} INFO - Dependencies all met for <TaskInstance: postgres_operator_dag_example.create_airflow_demo_schema manual__2022-09-21T21:10:41.541022+00:00 [queued]>
[2022-09-21T21:10:45.743+0000] {taskinstance.py:1171} INFO - Dependencies all met for <TaskInstance: postgres_operator_dag_example.create_airflow_demo_schema manual__2022-09-21T21:10:41.541022+00:00 [queued]>
[2022-09-21T21:10:45.746+0000] {taskinstance.py:1368} INFO - 
--------------------------------------------------------------------------------
[2022-09-21T21:10:45.747+0000] {taskinstance.py:1369} INFO - Starting attempt 1 of 2
[2022-09-21T21:10:45.748+0000] {taskinstance.py:1370} INFO - 
--------------------------------------------------------------------------------
[2022-09-21T21:10:45.771+0000] {taskinstance.py:1389} INFO - Executing <Task(PostgresOperator): create_airflow_demo_schema> on 2022-09-21 21:10:41.541022+00:00
[2022-09-21T21:10:45.800+0000] {standard_task_runner.py:52} INFO - Started process 59342 to run task
[2022-09-21T21:10:45.817+0000] {standard_task_runner.py:79} INFO - Running: ['***', 'tasks', 'run', 'postgres_operator_dag_example', 'create_***_demo_schema', 'manual__2022-09-21T21:10:41.541022+00:00', '--job-id', '5', '--raw', '--subdir', 'DAGS_FOLDER/postgresql_demo.py', '--cfg-path', '/tmp/tmpclgaqe3m', '--error-file', '/tmp/tmppxeoundm']
[2022-09-21T21:10:45.820+0000] {standard_task_runner.py:80} INFO - Job 5: Subtask create_***_demo_schema
[2022-09-21T21:10:53.422+0000] {task_command.py:371} INFO - Running <TaskInstance: postgres_operator_dag_example.create_airflow_demo_schema manual__2022-09-21T21:10:41.541022+00:00 [running]> on host 49fa11dd9034
[2022-09-21T21:10:53.856+0000] {taskinstance.py:1583} INFO - Exporting the following env vars:
AIRFLOW_CTX_DAG_OWNER=***
AIRFLOW_CTX_DAG_ID=postgres_operator_dag_example
AIRFLOW_CTX_TASK_ID=create_***_demo_schema
AIRFLOW_CTX_EXECUTION_DATE=2022-09-21T21:10:41.541022+00:00
AIRFLOW_CTX_TRY_NUMBER=1
AIRFLOW_CTX_DAG_RUN_ID=manual__2022-09-21T21:10:41.541022+00:00
[2022-09-21T21:10:54.267+0000] {taskinstance.py:1902} ERROR - Task failed with exception
Traceback (most recent call last):
  File "/home/airflow/.local/lib/python3.7/site-packages/airflow/providers/postgres/operators/postgres.py", line 92, in execute
    self.hook.run(self.sql, self.autocommit, parameters=self.parameters)
  File "/home/airflow/.local/lib/python3.7/site-packages/airflow/providers/common/sql/hooks/sql.py", line 288, in run
    with closing(self.get_conn()) as conn:
  File "/home/airflow/.local/lib/python3.7/site-packages/airflow/providers/postgres/hooks/postgres.py", line 86, in get_conn
    conn = deepcopy(self.connection or self.get_connection(conn_id))
  File "/home/airflow/.local/lib/python3.7/site-packages/airflow/hooks/base.py", line 67, in get_connection
    conn = Connection.get_connection_from_secrets(conn_id)
  File "/home/airflow/.local/lib/python3.7/site-packages/airflow/models/connection.py", line 430, in get_connection_from_secrets
    raise AirflowNotFoundException(f"The conn_id `{conn_id}` isn't defined")
airflow.exceptions.AirflowNotFoundException: The conn_id `postgres_default` isn't defined
[2022-09-21T21:10:54.418+0000] {taskinstance.py:1412} INFO - Marking task as UP_FOR_RETRY. dag_id=postgres_operator_dag_example, task_id=create_***_demo_schema, execution_date=20220921T211041, start_date=20220921T211045, end_date=20220921T211054
[2022-09-21T21:10:54.609+0000] {standard_task_runner.py:97} ERROR - Failed to execute job 5 for task create_***_demo_schema (The conn_id `postgres_default` isn't defined; 59342)
[2022-09-21T21:10:54.777+0000] {local_task_job.py:156} INFO - Task exited with return code 1
[2022-09-21T21:10:55.023+0000] {local_task_job.py:279} INFO - 0 downstream tasks scheduled from follow-on schedule check
