[2022-09-27T21:42:30.172+0000] {taskinstance.py:1171} INFO - Dependencies all met for <TaskInstance: preparing_motor_data_for_processing.test_ssh_operator manual__2022-09-27T21:41:18.386710+00:00 [queued]>
[2022-09-27T21:42:30.182+0000] {taskinstance.py:1171} INFO - Dependencies all met for <TaskInstance: preparing_motor_data_for_processing.test_ssh_operator manual__2022-09-27T21:41:18.386710+00:00 [queued]>
[2022-09-27T21:42:30.183+0000] {taskinstance.py:1368} INFO - 
--------------------------------------------------------------------------------
[2022-09-27T21:42:30.184+0000] {taskinstance.py:1369} INFO - Starting attempt 2 of 2
[2022-09-27T21:42:30.186+0000] {taskinstance.py:1370} INFO - 
--------------------------------------------------------------------------------
[2022-09-27T21:42:30.194+0000] {taskinstance.py:1389} INFO - Executing <Task(SSHOperator): test_ssh_operator> on 2022-09-27 21:41:18.386710+00:00
[2022-09-27T21:42:30.201+0000] {standard_task_runner.py:52} INFO - Started process 15284 to run task
[2022-09-27T21:42:30.204+0000] {standard_task_runner.py:79} INFO - Running: ['***', 'tasks', 'run', 'preparing_motor_data_for_processing', 'test_ssh_operator', 'manual__2022-09-27T21:41:18.386710+00:00', '--job-id', '37', '--raw', '--subdir', 'DAGS_FOLDER/preparing_motor_data_for_processing.py', '--cfg-path', '/tmp/tmpsd8xdixj', '--error-file', '/tmp/tmpbfxeh59d']
[2022-09-27T21:42:30.213+0000] {standard_task_runner.py:80} INFO - Job 37: Subtask test_ssh_operator
[2022-09-27T21:42:30.264+0000] {task_command.py:371} INFO - Running <TaskInstance: preparing_motor_data_for_processing.test_ssh_operator manual__2022-09-27T21:41:18.386710+00:00 [running]> on host 3431a65fe7cb
[2022-09-27T21:42:30.308+0000] {taskinstance.py:1583} INFO - Exporting the following env vars:
AIRFLOW_CTX_DAG_EMAIL=dataplatform@dynatronsoftware.com
AIRFLOW_CTX_DAG_OWNER=jsanchez
AIRFLOW_CTX_DAG_ID=preparing_motor_data_for_processing
AIRFLOW_CTX_TASK_ID=test_ssh_operator
AIRFLOW_CTX_EXECUTION_DATE=2022-09-27T21:41:18.386710+00:00
AIRFLOW_CTX_TRY_NUMBER=2
AIRFLOW_CTX_DAG_RUN_ID=manual__2022-09-27T21:41:18.386710+00:00
[2022-09-27T21:42:30.311+0000] {ssh.py:136} INFO - Creating ssh_client
[2022-09-27T21:42:30.312+0000] {ssh.py:114} INFO - ssh_hook is not provided or invalid. Trying ssh_conn_id to create SSHHook.
[2022-09-27T21:42:30.323+0000] {base.py:68} INFO - Using connection ID 'qa_ai_app1' for task execution.
[2022-09-27T21:42:30.328+0000] {ssh.py:287} WARNING - No Host Key Verification. This won't protect against Man-In-The-Middle attacks
[2022-09-27T21:42:30.767+0000] {transport.py:1874} INFO - Connected (version 2.0, client OpenSSH_7.6p1)
[2022-09-27T21:42:30.981+0000] {ssh.py:329} INFO - Failed to connect. Sleeping before retry attempt 1
[2022-09-27T21:42:34.941+0000] {transport.py:1874} INFO - Connected (version 2.0, client OpenSSH_7.6p1)
[2022-09-27T21:42:35.140+0000] {ssh.py:329} INFO - Failed to connect. Sleeping before retry attempt 2
[2022-09-27T21:42:39.429+0000] {transport.py:1874} INFO - Connected (version 2.0, client OpenSSH_7.6p1)
[2022-09-27T21:42:39.616+0000] {taskinstance.py:1902} ERROR - Task failed with exception
Traceback (most recent call last):
  File "/home/airflow/.local/lib/python3.7/site-packages/airflow/providers/ssh/operators/ssh.py", line 170, in execute
    with self.get_ssh_client() as ssh_client:
  File "/home/airflow/.local/lib/python3.7/site-packages/airflow/providers/ssh/operators/ssh.py", line 137, in get_ssh_client
    return self.get_hook().get_conn()
  File "/home/airflow/.local/lib/python3.7/site-packages/airflow/providers/ssh/hooks/ssh.py", line 336, in get_conn
    before_sleep=log_before_sleep,
  File "/home/airflow/.local/lib/python3.7/site-packages/tenacity/__init__.py", line 382, in __iter__
    do = self.iter(retry_state=retry_state)
  File "/home/airflow/.local/lib/python3.7/site-packages/tenacity/__init__.py", line 360, in iter
    raise retry_exc.reraise()
  File "/home/airflow/.local/lib/python3.7/site-packages/tenacity/__init__.py", line 193, in reraise
    raise self.last_attempt.result()
  File "/usr/local/lib/python3.7/concurrent/futures/_base.py", line 428, in result
    return self.__get_result()
  File "/usr/local/lib/python3.7/concurrent/futures/_base.py", line 384, in __get_result
    raise self._exception
  File "/home/airflow/.local/lib/python3.7/site-packages/airflow/providers/ssh/hooks/ssh.py", line 339, in get_conn
    client.connect(**connect_kwargs)
  File "/home/airflow/.local/lib/python3.7/site-packages/paramiko/client.py", line 446, in connect
    passphrase,
  File "/home/airflow/.local/lib/python3.7/site-packages/paramiko/client.py", line 766, in _auth
    raise saved_exception
  File "/home/airflow/.local/lib/python3.7/site-packages/paramiko/client.py", line 679, in _auth
    key_filename, pkey_class, passphrase
  File "/home/airflow/.local/lib/python3.7/site-packages/paramiko/client.py", line 588, in _key_from_filepath
    key = klass.from_private_key_file(key_path, password)
  File "/home/airflow/.local/lib/python3.7/site-packages/paramiko/pkey.py", line 249, in from_private_key_file
    key = cls(filename=filename, password=password)
  File "/home/airflow/.local/lib/python3.7/site-packages/paramiko/ed25519key.py", line 63, in __init__
    signing_key = self._parse_signing_key_data(data, password)
  File "/home/airflow/.local/lib/python3.7/site-packages/paramiko/ed25519key.py", line 97, in _parse_signing_key_data
    "Private key file is encrypted"
paramiko.ssh_exception.PasswordRequiredException: Private key file is encrypted
[2022-09-27T21:42:39.635+0000] {taskinstance.py:1412} INFO - Marking task as FAILED. dag_id=preparing_motor_data_for_processing, task_id=test_ssh_operator, execution_date=20220927T214118, start_date=20220927T214230, end_date=20220927T214239
[2022-09-27T21:42:39.646+0000] {warnings.py:110} WARNING - /home/***/.local/lib/python3.7/site-packages/***/utils/email.py:119: PendingDeprecationWarning: Fetching SMTP credentials from configuration variables will be deprecated in a future release. Please set credentials using a connection instead.
  send_mime_email(e_from=mail_from, e_to=recipients, mime_msg=msg, conn_id=conn_id, dryrun=dryrun)

[2022-09-27T21:42:39.648+0000] {configuration.py:562} WARNING - section/key [smtp/smtp_user] not found in config
[2022-09-27T21:42:39.650+0000] {email.py:228} INFO - Email alerting: attempt 1
[2022-09-27T21:42:39.660+0000] {configuration.py:562} WARNING - section/key [smtp/smtp_user] not found in config
[2022-09-27T21:42:39.661+0000] {email.py:228} INFO - Email alerting: attempt 1
[2022-09-27T21:42:39.663+0000] {taskinstance.py:1957} ERROR - Failed to send email to: dataplatform@dynatronsoftware.com
Traceback (most recent call last):
  File "/home/airflow/.local/lib/python3.7/site-packages/airflow/models/taskinstance.py", line 1463, in _run_raw_task
    self._execute_task_with_callbacks(context, test_mode)
  File "/home/airflow/.local/lib/python3.7/site-packages/airflow/models/taskinstance.py", line 1610, in _execute_task_with_callbacks
    result = self._execute_task(context, task_orig)
  File "/home/airflow/.local/lib/python3.7/site-packages/airflow/models/taskinstance.py", line 1671, in _execute_task
    result = execute_callable(context=context)
  File "/home/airflow/.local/lib/python3.7/site-packages/airflow/providers/ssh/operators/ssh.py", line 170, in execute
    with self.get_ssh_client() as ssh_client:
  File "/home/airflow/.local/lib/python3.7/site-packages/airflow/providers/ssh/operators/ssh.py", line 137, in get_ssh_client
    return self.get_hook().get_conn()
  File "/home/airflow/.local/lib/python3.7/site-packages/airflow/providers/ssh/hooks/ssh.py", line 336, in get_conn
    before_sleep=log_before_sleep,
  File "/home/airflow/.local/lib/python3.7/site-packages/tenacity/__init__.py", line 382, in __iter__
    do = self.iter(retry_state=retry_state)
  File "/home/airflow/.local/lib/python3.7/site-packages/tenacity/__init__.py", line 360, in iter
    raise retry_exc.reraise()
  File "/home/airflow/.local/lib/python3.7/site-packages/tenacity/__init__.py", line 193, in reraise
    raise self.last_attempt.result()
  File "/usr/local/lib/python3.7/concurrent/futures/_base.py", line 428, in result
    return self.__get_result()
  File "/usr/local/lib/python3.7/concurrent/futures/_base.py", line 384, in __get_result
    raise self._exception
  File "/home/airflow/.local/lib/python3.7/site-packages/airflow/providers/ssh/hooks/ssh.py", line 339, in get_conn
    client.connect(**connect_kwargs)
  File "/home/airflow/.local/lib/python3.7/site-packages/paramiko/client.py", line 446, in connect
    passphrase,
  File "/home/airflow/.local/lib/python3.7/site-packages/paramiko/client.py", line 766, in _auth
    raise saved_exception
  File "/home/airflow/.local/lib/python3.7/site-packages/paramiko/client.py", line 679, in _auth
    key_filename, pkey_class, passphrase
  File "/home/airflow/.local/lib/python3.7/site-packages/paramiko/client.py", line 588, in _key_from_filepath
    key = klass.from_private_key_file(key_path, password)
  File "/home/airflow/.local/lib/python3.7/site-packages/paramiko/pkey.py", line 249, in from_private_key_file
    key = cls(filename=filename, password=password)
  File "/home/airflow/.local/lib/python3.7/site-packages/paramiko/ed25519key.py", line 63, in __init__
    signing_key = self._parse_signing_key_data(data, password)
  File "/home/airflow/.local/lib/python3.7/site-packages/paramiko/ed25519key.py", line 97, in _parse_signing_key_data
    "Private key file is encrypted"
paramiko.ssh_exception.PasswordRequiredException: Private key file is encrypted

During handling of the above exception, another exception occurred:

Traceback (most recent call last):
  File "/home/airflow/.local/lib/python3.7/site-packages/airflow/models/taskinstance.py", line 2339, in email_alert
    send_email(task.email, subject, html_content)
  File "/home/airflow/.local/lib/python3.7/site-packages/airflow/utils/email.py", line 71, in send_email
    **kwargs,
  File "/home/airflow/.local/lib/python3.7/site-packages/airflow/utils/email.py", line 119, in send_email_smtp
    send_mime_email(e_from=mail_from, e_to=recipients, mime_msg=msg, conn_id=conn_id, dryrun=dryrun)
  File "/home/airflow/.local/lib/python3.7/site-packages/airflow/utils/email.py", line 230, in send_mime_email
    smtp_conn = _get_smtp_connection(smtp_host, smtp_port, smtp_timeout, smtp_ssl)
  File "/home/airflow/.local/lib/python3.7/site-packages/airflow/utils/email.py", line 264, in _get_smtp_connection
    else smtplib.SMTP(host=host, port=port, timeout=timeout)
  File "/usr/local/lib/python3.7/smtplib.py", line 251, in __init__
    (code, msg) = self.connect(host, port)
  File "/usr/local/lib/python3.7/smtplib.py", line 336, in connect
    self.sock = self._get_socket(host, port, self.timeout)
  File "/usr/local/lib/python3.7/smtplib.py", line 307, in _get_socket
    self.source_address)
  File "/usr/local/lib/python3.7/socket.py", line 728, in create_connection
    raise err
  File "/usr/local/lib/python3.7/socket.py", line 716, in create_connection
    sock.connect(sa)
OSError: [Errno 99] Cannot assign requested address

During handling of the above exception, another exception occurred:

Traceback (most recent call last):
  File "/home/airflow/.local/lib/python3.7/site-packages/airflow/models/taskinstance.py", line 1955, in handle_failure
    self.email_alert(error, task)
  File "/home/airflow/.local/lib/python3.7/site-packages/airflow/models/taskinstance.py", line 2341, in email_alert
    send_email(task.email, subject, html_content_err)
  File "/home/airflow/.local/lib/python3.7/site-packages/airflow/utils/email.py", line 71, in send_email
    **kwargs,
  File "/home/airflow/.local/lib/python3.7/site-packages/airflow/utils/email.py", line 119, in send_email_smtp
    send_mime_email(e_from=mail_from, e_to=recipients, mime_msg=msg, conn_id=conn_id, dryrun=dryrun)
  File "/home/airflow/.local/lib/python3.7/site-packages/airflow/utils/email.py", line 230, in send_mime_email
    smtp_conn = _get_smtp_connection(smtp_host, smtp_port, smtp_timeout, smtp_ssl)
  File "/home/airflow/.local/lib/python3.7/site-packages/airflow/utils/email.py", line 264, in _get_smtp_connection
    else smtplib.SMTP(host=host, port=port, timeout=timeout)
  File "/usr/local/lib/python3.7/smtplib.py", line 251, in __init__
    (code, msg) = self.connect(host, port)
  File "/usr/local/lib/python3.7/smtplib.py", line 336, in connect
    self.sock = self._get_socket(host, port, self.timeout)
  File "/usr/local/lib/python3.7/smtplib.py", line 307, in _get_socket
    self.source_address)
  File "/usr/local/lib/python3.7/socket.py", line 728, in create_connection
    raise err
  File "/usr/local/lib/python3.7/socket.py", line 716, in create_connection
    sock.connect(sa)
OSError: [Errno 99] Cannot assign requested address
[2022-09-27T21:42:39.680+0000] {standard_task_runner.py:97} ERROR - Failed to execute job 37 for task test_ssh_operator (Private key file is encrypted; 15284)
[2022-09-27T21:42:39.731+0000] {local_task_job.py:156} INFO - Task exited with return code 1
[2022-09-27T21:42:39.767+0000] {local_task_job.py:279} INFO - 0 downstream tasks scheduled from follow-on schedule check
