[2022-09-27T21:53:56.292+0000] {taskinstance.py:1171} INFO - Dependencies all met for <TaskInstance: preparing_motor_data_for_processing.call_ssh_task manual__2022-09-27T21:53:54.165153+00:00 [queued]>
[2022-09-27T21:53:56.304+0000] {taskinstance.py:1171} INFO - Dependencies all met for <TaskInstance: preparing_motor_data_for_processing.call_ssh_task manual__2022-09-27T21:53:54.165153+00:00 [queued]>
[2022-09-27T21:53:56.305+0000] {taskinstance.py:1368} INFO - 
--------------------------------------------------------------------------------
[2022-09-27T21:53:56.306+0000] {taskinstance.py:1369} INFO - Starting attempt 1 of 2
[2022-09-27T21:53:56.307+0000] {taskinstance.py:1370} INFO - 
--------------------------------------------------------------------------------
[2022-09-27T21:53:56.319+0000] {taskinstance.py:1389} INFO - Executing <Task(PythonOperator): call_ssh_task> on 2022-09-27 21:53:54.165153+00:00
[2022-09-27T21:53:56.327+0000] {standard_task_runner.py:52} INFO - Started process 15845 to run task
[2022-09-27T21:53:56.330+0000] {standard_task_runner.py:79} INFO - Running: ['***', 'tasks', 'run', 'preparing_motor_data_for_processing', 'call_ssh_task', 'manual__2022-09-27T21:53:54.165153+00:00', '--job-id', '40', '--raw', '--subdir', 'DAGS_FOLDER/preparing_motor_data_for_processing.py', '--cfg-path', '/tmp/tmpqwnz2pyc', '--error-file', '/tmp/tmp4wei1qdx']
[2022-09-27T21:53:56.333+0000] {standard_task_runner.py:80} INFO - Job 40: Subtask call_ssh_task
[2022-09-27T21:53:56.406+0000] {task_command.py:371} INFO - Running <TaskInstance: preparing_motor_data_for_processing.call_ssh_task manual__2022-09-27T21:53:54.165153+00:00 [running]> on host 3431a65fe7cb
[2022-09-27T21:53:56.482+0000] {taskinstance.py:1583} INFO - Exporting the following env vars:
AIRFLOW_CTX_DAG_OWNER=jsanchez
AIRFLOW_CTX_DAG_ID=preparing_motor_data_for_processing
AIRFLOW_CTX_TASK_ID=call_ssh_task
AIRFLOW_CTX_EXECUTION_DATE=2022-09-27T21:53:54.165153+00:00
AIRFLOW_CTX_TRY_NUMBER=1
AIRFLOW_CTX_DAG_RUN_ID=manual__2022-09-27T21:53:54.165153+00:00
[2022-09-27T21:53:56.505+0000] {base.py:68} INFO - Using connection ID 'qa_ai_app1' for task execution.
[2022-09-27T21:53:56.540+0000] {ssh.py:287} WARNING - No Host Key Verification. This won't protect against Man-In-The-Middle attacks
[2022-09-27T21:53:56.987+0000] {transport.py:1874} INFO - Connected (version 2.0, client OpenSSH_7.6p1)
[2022-09-27T21:53:57.226+0000] {ssh.py:329} INFO - Failed to connect. Sleeping before retry attempt 1
[2022-09-27T21:54:00.829+0000] {transport.py:1874} INFO - Connected (version 2.0, client OpenSSH_7.6p1)
[2022-09-27T21:54:01.023+0000] {ssh.py:329} INFO - Failed to connect. Sleeping before retry attempt 2
[2022-09-27T21:54:04.468+0000] {transport.py:1874} INFO - Connected (version 2.0, client OpenSSH_7.6p1)
[2022-09-27T21:54:04.669+0000] {taskinstance.py:1902} ERROR - Task failed with exception
Traceback (most recent call last):
  File "/home/airflow/.local/lib/python3.7/site-packages/airflow/operators/python.py", line 171, in execute
    return_value = self.execute_callable()
  File "/home/airflow/.local/lib/python3.7/site-packages/airflow/operators/python.py", line 189, in execute_callable
    return self.python_callable(*self.op_args, **self.op_kwargs)
  File "/opt/airflow/dags/preparing_motor_data_for_processing.py", line 31, in create_the_file
    ssh_client = ssh.get_conn()
  File "/home/airflow/.local/lib/python3.7/site-packages/airflow/providers/ssh/hooks/ssh.py", line 336, in get_conn
    before_sleep=log_before_sleep,
  File "/home/airflow/.local/lib/python3.7/site-packages/tenacity/__init__.py", line 382, in __iter__
    do = self.iter(retry_state=retry_state)
  File "/home/airflow/.local/lib/python3.7/site-packages/tenacity/__init__.py", line 360, in iter
    raise retry_exc.reraise()
  File "/home/airflow/.local/lib/python3.7/site-packages/tenacity/__init__.py", line 193, in reraise
    raise self.last_attempt.result()
  File "/usr/local/lib/python3.7/concurrent/futures/_base.py", line 428, in result
    return self.__get_result()
  File "/usr/local/lib/python3.7/concurrent/futures/_base.py", line 384, in __get_result
    raise self._exception
  File "/home/airflow/.local/lib/python3.7/site-packages/airflow/providers/ssh/hooks/ssh.py", line 339, in get_conn
    client.connect(**connect_kwargs)
  File "/home/airflow/.local/lib/python3.7/site-packages/paramiko/client.py", line 446, in connect
    passphrase,
  File "/home/airflow/.local/lib/python3.7/site-packages/paramiko/client.py", line 766, in _auth
    raise saved_exception
  File "/home/airflow/.local/lib/python3.7/site-packages/paramiko/client.py", line 679, in _auth
    key_filename, pkey_class, passphrase
  File "/home/airflow/.local/lib/python3.7/site-packages/paramiko/client.py", line 588, in _key_from_filepath
    key = klass.from_private_key_file(key_path, password)
  File "/home/airflow/.local/lib/python3.7/site-packages/paramiko/pkey.py", line 249, in from_private_key_file
    key = cls(filename=filename, password=password)
  File "/home/airflow/.local/lib/python3.7/site-packages/paramiko/ed25519key.py", line 63, in __init__
    signing_key = self._parse_signing_key_data(data, password)
  File "/home/airflow/.local/lib/python3.7/site-packages/paramiko/ed25519key.py", line 97, in _parse_signing_key_data
    "Private key file is encrypted"
paramiko.ssh_exception.PasswordRequiredException: Private key file is encrypted
[2022-09-27T21:54:04.791+0000] {taskinstance.py:1412} INFO - Marking task as UP_FOR_RETRY. dag_id=preparing_motor_data_for_processing, task_id=call_ssh_task, execution_date=20220927T215354, start_date=20220927T215356, end_date=20220927T215404
[2022-09-27T21:54:04.810+0000] {standard_task_runner.py:97} ERROR - Failed to execute job 40 for task call_ssh_task (Private key file is encrypted; 15845)
[2022-09-27T21:54:04.858+0000] {local_task_job.py:156} INFO - Task exited with return code 1
[2022-09-27T21:54:04.882+0000] {local_task_job.py:279} INFO - 0 downstream tasks scheduled from follow-on schedule check
